<mujoco model="ur5e">
  <compiler angle="radian" meshdir="assets" autolimits="true" />
  <option integrator="implicitfast" />
  <default>
    <default class="ur5e">
      <default class="visual">
        <geom type="mesh" contype="0" conaffinity="0" group="2" />
      </default>
      <default class="collision">
        <geom type="capsule" group="3" />
        <default class="eef_collision">
          <geom type="cylinder" />
        </default>
      </default>
      <joint axis="0 1 0" range="-6.28319 6.28319" />
      <default class="joint_limited">
        <joint range="-3.1415 3.1415" />
      </default>
      <default class="position">
        <position ctrlrange="-6.2831 6.2831" kp="2000" kv="100" forcerange="-150 150" />
        <default class="position_limited">
          <position ctrlrange="-3.1415 3.1415" />
        </default>
        <default class="position_small">
          <position kp="500" kv="25" forcerange="-28 28" />
        </default>
      </default>
    </default>
  </default>
  <asset>
    <material name="black" rgba="0.033 0.033 0.033 1" />
    <material name="jointgray" rgba="0.278 0.278 0.278 1" />
    <material name="linkgray" rgba="0.82 0.82 0.82 1" />
    <material name="urblue" rgba="0.49 0.678 0.8 1" />
    <mesh file="base_0.obj" />
    <mesh file="base_1.obj" />
    <mesh file="shoulder_0.obj" />
    <mesh file="shoulder_1.obj" />
    <mesh file="shoulder_2.obj" />
    <mesh file="upperarm_0.obj" />
    <mesh file="upperarm_1.obj" />
    <mesh file="upperarm_2.obj" />
    <mesh file="upperarm_3.obj" />
    <mesh file="forearm_0.obj" />
    <mesh file="forearm_1.obj" />
    <mesh file="forearm_2.obj" />
    <mesh file="forearm_3.obj" />
    <mesh file="wrist1_0.obj" />
    <mesh file="wrist1_1.obj" />
    <mesh file="wrist1_2.obj" />
    <mesh file="wrist2_0.obj" />
    <mesh file="wrist2_1.obj" />
    <mesh file="wrist2_2.obj" />
    <mesh file="wrist3.obj" />
  </asset>
  <worldbody>
    <body name="base" quat="1 0 0 1" childclass="ur5e">
      <inertial mass="4" pos="0 0 0" diaginertia="0.00443333156 0.00443333156 0.0072" />
      <geom mesh="base_0" material="black" class="visual" />
      <geom mesh="base_1" material="jointgray" class="visual" />
      <body name="shoulder_link" pos="0 0 0.163">
        <inertial mass="3.70000326474" pos="0 0 0" diaginertia="7.88343938225e-08 0.0102560854813 0.0102560854813" quat="0.707106781187 0 -0.707106781187 0" />
        <joint name="shoulder_pan" axis="0 0 1" />
        <geom mesh="shoulder_0" material="urblue" class="visual" />
        <geom mesh="shoulder_1" material="black" class="visual" />
        <geom mesh="shoulder_2" material="jointgray" class="visual" />
        <geom class="collision" size="0.06 0.06" pos="0 0 -0.04" />
        <body name="upper_arm_link" pos="0 0.138 0" quat="1 0 1 0">
          <inertial mass="10.4428446061" pos="-0.00351305434309 -0.148382675471 0.194271711342" diaginertia="1.83244909246e-08 0.497372764755 0.497372816565" quat="0.954777526501 -0.147979747048 0.194689787943 -0.169108710075" />
          <joint name="shoulder_lift" />
          <geom mesh="upperarm_0" material="linkgray" class="visual" />
          <geom mesh="upperarm_1" material="black" class="visual" />
          <geom mesh="upperarm_2" material="jointgray" class="visual" />
          <geom mesh="upperarm_3" material="urblue" class="visual" />
          <geom class="collision" pos="0 -0.04 0" quat="1 1 0 0" size="0.06 0.06" />
          <geom class="collision" size="0.05 0.2" pos="0 0 0.2" />
          <body name="forearm_link" pos="0 -0.131 0.425">
            <inertial mass="2.20333437022" pos="0.00536685976622 0.265737467298 0.300910295989" diaginertia="0.0863616836403 0.405945272141 0.492306962693" quat="-0.302781379519 0.853134307867 -0.329327628248 0.268381449117" />
            <joint name="elbow" class="joint_limited" />
            <geom mesh="forearm_0" material="urblue" class="visual" />
            <geom mesh="forearm_1" material="linkgray" class="visual" />
            <geom mesh="forearm_2" material="black" class="visual" />
            <geom mesh="forearm_3" material="jointgray" class="visual" />
            <geom class="collision" pos="0 0.08 0" quat="1 1 0 0" size="0.055 0.06" />
            <geom class="collision" size="0.038 0.19" pos="0 0 0.2" />
            <body name="wrist_1_link" pos="0 0 0.392" quat="1 0 1 0">
              <inertial mass="1.3360172296" pos="-0.00202009337294 0.454785766841 -0.0748917210054" diaginertia="1.61327009338e-08 0.891188675982 0.891188709899" quat="0.586217417583 0.272993516615 0.438194254995 0.6243472384" />
              <joint name="wrist_1" />
              <geom mesh="wrist1_0" material="black" class="visual" />
              <geom mesh="wrist1_1" material="urblue" class="visual" />
              <geom mesh="wrist1_2" material="jointgray" class="visual" />
              <geom class="collision" pos="0 0.05 0" quat="1 1 0 0" size="0.04 0.07" />
              <body name="wrist_2_link" pos="0 0.127 0">
                <inertial mass="1.83983968825" pos="0.00261303568376 0.0790182941654 0.158351374953" diaginertia="3.24525545679e-08 0.041265116675 0.0412651555299" quat="-0.226567812471 0.327351712068 -0.470792931387 0.787313088113" />
                <joint name="wrist_2" axis="0 0 1" />
                <geom mesh="wrist2_0" material="black" class="visual" />
                <geom mesh="wrist2_1" material="urblue" class="visual" />
                <geom mesh="wrist2_2" material="jointgray" class="visual" />
                <geom class="collision" size="0.04 0.06" pos="0 0 0.04" />
                <geom class="collision" pos="0 0.02 0.1" quat="1 1 0 0" size="0.04 0.04" />
                <body name="wrist_3_link" pos="0 0 0.1">
                  <inertial mass="0.788425378583" pos="0.00015250572387 0.0691418353174 0.00306121265554" quat="0.456690721238 0.536733325544 -0.298459316407 0.64364039559" diaginertia="0.0127828401268 0.0573967155514 0.0701795574531" />
                  <joint name="wrist_3" />
                  <geom material="linkgray" mesh="wrist3" class="visual" />
                  <geom name="wrist_3_link" class="collision" pos="0 0.025 0" quat="1 1 0 0" size="0.04 0.05" />
                  <site name="attachment_site" size="0.01" pos="0 0.1 0" quat="-1 1 1 1" rgba="1 0 0 1" group="1" />
                </body>
              </body>
            </body>
          </body>
        </body>
      </body>
    </body>
  </worldbody>
  <actuator>
    <position class="position" name="shoulder_pan" joint="shoulder_pan" />
    <position class="position" name="shoulder_lift" joint="shoulder_lift" />
    <position class="position_limited" name="elbow" joint="elbow" />
    <position class="position_small" name="wrist_1" joint="wrist_1" />
    <position class="position_small" name="wrist_2" joint="wrist_2" />
    <position class="position_small" name="wrist_3" joint="wrist_3" />
  </actuator>
  <keyframe>
    <key name="home" qpos="-1.5708 -1.5708 1.5708 -1.5708 -1.5708 0" ctrl="-1.5708 -1.5708 1.5708 -1.5708 -1.5708 0" />
  </keyframe>
</mujoco>