<?xml version='1.0' encoding='utf-8'?>
<robot name="ur5">
  <mujoco>
    <compiler meshdir="assets" balanceinertia="true" discardvisual="false" />
  </mujoco>
  <!-- <xacro:include filename="$(find realsense_ros_gazebo)/xacro/tracker.xacro"/> -->
  <!-- <xacro:include filename="$(find realsense_ros_gazebo)/xacro/depthcam.xacro"/> -->
  <!-- measured from model -->
  <!--property name="shoulder_height" value="0.089159" /-->
  <!--property name="shoulder_offset" value="0.13585" /-->
  <!-- shoulder_offset - elbow_offset + wrist_1_length = 0.10915 -->
  <!--property name="upper_arm_length" value="0.42500" /-->
  <!--property name="elbow_offset" value="0.1197" /-->
  <!-- CAD measured -->
  <!--property name="forearm_length" value="0.39225" /-->
  <!--property name="wrist_1_length" value="0.093" /-->
  <!-- CAD measured -->
  <!--property name="wrist_2_length" value="0.09465" /-->
  <!-- In CAD this distance is 0.930, but in the spec it is 0.09465 -->
  <!--property name="wrist_3_length" value="0.0823" /-->
  <!-- manually measured -->
  <link name="base_link">
    <visual>
      <geometry>
        <mesh filename="assets/base.stl" />
      </geometry>
      <material name="LightGrey">
        <color rgba="0.7 0.7 0.7 1.0" />
      </material>
    </visual>
    <collision>
      <geometry>
        <mesh filename="assets/base.stl" />
      </geometry>
    </collision>
    <inertial>
      <mass value="4.0" />
      <origin rpy="0 0 0" xyz="0.0 0.0 0.0" />
      <inertia ixx="0.00443333156" ixy="0.0" ixz="0.0" iyy="0.00443333156" iyz="0.0" izz="0.0072" />
    </inertial>
  </link>
  <joint name="shoulder_pan_joint" type="revolute">
    <parent link="base_link" />
    <child link="shoulder_link" />
    <origin rpy="0.0 0.0 0.0" xyz="0.0 0.0 0.089159" />
    <axis xyz="0 0 1" />
    <limit effort="150.0" lower="-3.141592653589793" upper="3.141592653589793" velocity="3.15" />
    <dynamics damping="9.57508767926301" friction="13.3198786870032" />
  </joint>
  <link name="shoulder_link">
    <visual>
      <geometry>
        <mesh filename="assets/shoulder.stl" />
      </geometry>
      <material name="LightGrey">
        <color rgba="0.7 0.7 0.7 1.0" />
      </material>
    </visual>
    <collision>
      <geometry>
        <mesh filename="assets/shoulder.stl" />
      </geometry>
    </collision>
    <inertial>
      <mass value="3.76314433393469" />
      <origin rpy="0 0 0" xyz="3.48564872801904e-09 6.45488025775008e-06 0.00349615578492665" />
      <inertia ixx="0.00238114580899604" ixy="0" ixz="0" iyy="0.00238114530333087" iyz="0" izz="0.00666" />
    </inertial>
  </link>
  <joint name="shoulder_lift_joint" type="revolute">
    <parent link="shoulder_link" />
    <child link="upper_arm_link" />
    <origin rpy="0.0 1.5707963267948966 0.0" xyz="0.0 0.13585 0.0" />
    <axis xyz="0 1 0" />
    <limit effort="150.0" lower="-3.141592653589793" upper="3.141592653589793" velocity="3.15" />
    <dynamics damping="6.97856381562932" friction="5.89416885440174" />
  </joint>
  <link name="upper_arm_link">
    <visual>
      <geometry>
        <mesh filename="assets/upperarm.stl" />
      </geometry>
      <material name="LightGrey">
        <color rgba="0.7 0.7 0.7 1.0" />
      </material>
    </visual>
    <collision>
      <geometry>
        <mesh filename="assets/upperarm.stl" />
      </geometry>
    </collision>
    <inertial>
      <mass value="140.415852668972" />
      <origin rpy="0 0 0" xyz="-0.000990968143618101 -0.0193163441448193 0.0142281541062296" />
      <inertia ixx="0.137379267305006" ixy="0.0585045413135921" ixz="0.15460493059121" iyy="0.319076539754203" iyz="-0.0454743130511861" izz="0.216113513605439" />
    </inertial>
  </link>
  <joint name="elbow_joint" type="revolute">
    <parent link="upper_arm_link" />
    <child link="forearm_link" />
    <origin rpy="0.0 0.0 0.0" xyz="0.0 -0.1197 0.425" />
    <axis xyz="0 1 0" />
    <limit effort="150.0" lower="-3.141592653589793" upper="3.141592653589793" velocity="3.15" />
    <dynamics damping="6.20602342071657" friction="8.79158605826971" />
  </joint>
  <link name="forearm_link">
    <visual>
      <geometry>
        <mesh filename="assets/forearm.stl" />
      </geometry>
      <material name="LightGrey">
        <color rgba="0.7 0.7 0.7 1.0" />
      </material>
    </visual>
    <collision>
      <geometry>
        <mesh filename="assets/forearm.stl" />
      </geometry>
    </collision>
    <inertial>
      <mass value="1.43810933401384" />
      <origin rpy="0 0 0" xyz="0.0356009651164481 0.0418574247458284 0.197482692154112" />
      <inertia ixx="0.049443313556" ixy="0" ixz="0" iyy="0.049443313556" iyz="0" izz="0.004095" />
    </inertial>
  </link>
  <joint name="wrist_1_joint" type="revolute">
    <parent link="forearm_link" />
    <child link="wrist_1_link" />
    <origin rpy="0.0 1.5707963267948966 0.0" xyz="0.0 0.0 0.39225" />
    <axis xyz="0 1 0" />
    <limit effort="28.0" lower="-3.141592653589793" upper="3.141592653589793" velocity="3.2" />
    <dynamics damping="1.35799435113143" friction="1.88688051268401" />
  </joint>
  <link name="wrist_1_link">
    <visual>
      <geometry>
        <mesh filename="assets/wrist1.stl" />
      </geometry>
      <material name="LightGrey">
        <color rgba="0.7 0.7 0.7 1.0" />
      </material>
    </visual>
    <collision>
      <geometry>
        <mesh filename="assets/wrist1.stl" />
      </geometry>
    </collision>
    <inertial>
      <mass value="2.59357794901404" />
      <origin rpy="0 0 0" xyz="0.00998476330183867 0.163379762010861 0.00513490731643428" />
      <inertia ixx="0.11117275553088" ixy="0" ixz="0" iyy="0.11117275553088" iyz="0" izz="0.21942" />
    </inertial>
  </link>
  <joint name="wrist_2_joint" type="revolute">
    <parent link="wrist_1_link" />
    <child link="wrist_2_link" />
    <origin rpy="0.0 0.0 0.0" xyz="0.0 0.093 0.0" />
    <axis xyz="0 0 1" />
    <limit effort="28.0" lower="-3.141592653589793" upper="3.141592653589793" velocity="3.2" />
    <dynamics damping="1.78943818353346" friction="1.32620198889296" />
  </joint>
  <link name="wrist_2_link">
    <visual>
      <geometry>
        <mesh filename="assets/wrist2.stl" />
      </geometry>
      <material name="LightGrey">
        <color rgba="0.7 0.7 0.7 1.0" />
      </material>
    </visual>
    <collision>
      <geometry>
        <mesh filename="assets/wrist2.stl" />
      </geometry>
    </collision>
    <inertial>
      <mass value="0.173084611856294" />
      <origin rpy="0 0 0" xyz="-0.028119830393735 0.0366210291897761 0.0959570612770406" />
      <inertia ixx="0.11117275553088" ixy="0" ixz="0" iyy="0.11117275553088" iyz="0" izz="0.21942" />
    </inertial>
  </link>
  <joint name="wrist_3_joint" type="revolute">
    <parent link="wrist_2_link" />
    <child link="wrist_3_link" />
    <origin rpy="0.0 0.0 0.0" xyz="0.0 0.0 0.09465" />
    <axis xyz="0 1 0" />
    <limit effort="28.0" lower="-3.141592653589793" upper="3.141592653589793" velocity="3.2" />
    <dynamics damping="1.49029746722104" friction="1.72381999387903" />
  </joint>
  <link name="wrist_3_link">
    <visual>
      <geometry>
        <mesh filename="assets/wrist3.stl" />
      </geometry>
      <material name="LightGrey">
        <color rgba="0.7 0.7 0.7 1.0" />
      </material>
    </visual>
    <collision>
      <geometry>
        <mesh filename="assets/wrist3.stl" />
      </geometry>
    </collision>
    <inertial>
      <mass value="2.16975057226342" />
      <origin rpy="0 0 0" xyz="0.013149377109144 0.0814364402927532 0.00243013873446396" />
      <inertia ixx="0.00249014075718443" ixy="-0.000148747716670646" ixz="-0.000642406252146262" iyy="0.00253803834679075" iyz="-0.000547256711653801" izz="0.000301350097064623" />
    </inertial>
  </link>
  <joint name="ee_fixed_joint" type="fixed">
    <parent link="wrist_3_link" />
    <child link="ee_link" />
    <origin rpy="0.0 0.0 1.5707963267948966" xyz="0.0 0.0823 0.0" />
  </joint>
  <link name="ee_link">
    <collision>
      <geometry>
        <box size="0.01 0.01 0.01" />
      </geometry>
      <origin rpy="0 0 0" xyz="-0.01 0 0" />
    </collision>
  </link>
  <!-- nothing to do here at the moment -->
  <!-- ROS base_link to UR 'Base' Coordinates transform -->
  <link name="base" />
  <joint name="base_link-base_fixed_joint" type="fixed">
    <!-- NOTE: this rotation is only needed as long as base_link itself is
                 not corrected wrt the real robot (ie: rotated over 180
                 degrees)
      -->
    <origin rpy="0 0 -3.141592653589793" xyz="0 0 0" />
    <parent link="base_link" />
    <child link="base" />
  </joint>
  <!-- Frame coincident with all-zeros TCP on UR controller -->
  <link name="tool0" />
  <joint name="wrist_3_link-tool0_fixed_joint" type="fixed">
    <origin rpy="-1.5707963267948966 0 0" xyz="0 0.0823 0" />
    <parent link="wrist_3_link" />
    <child link="tool0" />
  </joint>
  <link name="support">
    <visual>
      <geometry>
        <cylinder length="0.03" radius="0.02" />
      </geometry>
      <origin rpy="0.0 0.0 0.0" xyz="0.0 0.0 0.0" />
      <material name="black">
        <color rgba="0.8 0.2 0.0 0.8" />
      </material>
    </visual>
    <collision>
      <geometry>
        <cylinder length="0.03" radius="0.02" />
      </geometry>
      <origin rpy="0.0 0.0 0.0" xyz="0.0 0.0 0.0" />
    </collision>
  </link>
  <joint name="support2wrist_3_link" type="fixed">
    <parent link="wrist_3_link" />
    <child link="support" />
    <origin xyz="0 0.05 0.05" />
  </joint>
  <!-- <xacro:realsense_d435 sensor_name="d435" parent_link="support" rate="10">
    <origin rpy="0 0 1.57 " xyz="0 0 0.01"/>
    </xacro:realsense_d435> -->
  <link name="world" />
  <joint name="world_joint" type="fixed">
    <parent link="world" />
    <child link="base_link" />
    <origin rpy="0.0 0.0 0.0" xyz="0.0 0.0 0.0" />
  </joint>
  <!-- Robotiq Coupler -->
  <!--  + Height added by the coupler: 8mm -->
  <!--  + Reference frame: at the middle (4mm) -->
  <link name="robotiq_coupler">
    <visual>
      <geometry>
        <mesh filename="assets/robotiq_85_coupler.stl" />
      </geometry>
      <material name="flat_black">
        <color rgba="0.0 0.0 0.0 1.0" />
      </material>
    </visual>
    <collision>
      <geometry>
        <mesh filename="assets/robotiq_85_coupler.stl" />
      </geometry>
    </collision>
    <inertial>
      <origin rpy="0 0 0" xyz="2.073e-05   1.45286e-03  -1.1049e-03" />
      <mass value="0.168" />
      <inertia ixx="6.69695624e-05" ixy="5.21511788e-09" ixz="-2.74383009e-08" iyy="7.85088161e-05" iyz="5.41105193e-07" izz="1.41819717e-04" />
    </inertial>
  </link>
  <joint name="robotiq_coupler_joint" type="fixed">
    <origin rpy="0 0 -1.5707963267948966" xyz="0 0 0.004" />
    <parent link="tool0" />
    <child link="robotiq_coupler" />
  </joint>
  <!-- Equivalent to the OpenRAVE manipulator denso_robotiq_85_gripper -->
  <!-- <link name="denso_robotiq_85_gripper" /> -->
  <!-- <joint name="manipulator_dummy_joint" type="fixed"> -->
  <!--   <origin xyz="0 0 0.1441" rpy="0 0 0" /> -->
  <!--   <parent link="robotiq_coupler"/> -->
  <!--   <child link="denso_robotiq_85_gripper"/> -->
  <!-- </joint> -->
  <joint name="robotiq_85_base_joint" type="fixed">
    <parent link="robotiq_coupler" />
    <child link="robotiq_85_base_link" />
    <origin rpy="0 -1.5707963267948966 3.141592653589793" xyz="0 0 0.004" />
  </joint>
  <link name="robotiq_85_base_link">
    <visual>
      <geometry>
        <mesh filename="assets/robotiq_85_base_link.stl" />
      </geometry>
    </visual>
    <collision>
      <geometry>
        <mesh filename="assets/robotiq_85_base_link.stl" />
      </geometry>
    </collision>
    <inertial>
      <mass value="0.636951" />
      <origin xyz="0.0 0.0 0.0" />
      <inertia ixx="0.000380" ixy="0.000000" ixz="0.000000" iyx="0.000000" iyy="0.001110" iyz="0.000000" izx="0.000000" izy="0.000000" izz="0.001171" />
    </inertial>
  </link>
  <joint name="robotiq_85_left_knuckle_joint" type="revolute">
    <parent link="robotiq_85_base_link" />
    <child link="robotiq_85_left_knuckle_link" />
    <axis xyz="0 0 1" />
    <origin rpy="3.141592653589793 0.0 0.0" xyz="0.05490451627 0.03060114443 0.0" />
    <limit effort="1000" lower="0.0" upper="0.80285" velocity="0.5" />
  </joint>
  <joint name="robotiq_85_right_knuckle_joint" type="continuous">
    <parent link="robotiq_85_base_link" />
    <child link="robotiq_85_right_knuckle_link" />
    <axis xyz="0 0 1" />
    <origin rpy="0.0 0.0 0.0" xyz="0.05490451627 -0.03060114443 0.0" />
    <limit effort="1000" lower="-3.14" upper="3.14" velocity="100.0" />
    <mimic joint="robotiq_85_left_knuckle_joint" />
  </joint>
  <link name="robotiq_85_left_knuckle_link">
    <visual>
      <geometry>
        <mesh filename="assets/robotiq_85_knuckle_link.stl" />
      </geometry>
    </visual>
    <collision>
      <geometry>
        <mesh filename="assets/robotiq_85_knuckle_link.stl" />
      </geometry>
    </collision>
    <inertial>
      <mass value="0.00853198276973456" />
      <origin xyz="-0.000200000000003065 0.0199435877845359 0.0292245259211331" />
      <inertia ixx="2.89328108496468E-06" ixy="0.0" ixz="0.0" iyx="0.0" iyy="1.86719750325683E-06" iyz="-1.21858577871576E-06" izx="0.0" izy="-1.21858577871576E-06" izz="1.21905238907251E-06" />
    </inertial>
  </link>
  <link name="robotiq_85_right_knuckle_link">
    <visual>
      <geometry>
        <mesh filename="assets/robotiq_85_knuckle_link.stl" />
      </geometry>
    </visual>
    <collision>
      <geometry>
        <mesh filename="assets/robotiq_85_knuckle_link.stl" />
      </geometry>
    </collision>
    <inertial>
      <mass value="0.00853198276973456" />
      <origin xyz="-0.000200000000003065 0.0199435877845359 0.0292245259211331" />
      <inertia ixx="2.89328108496468E-06" ixy="0.0" ixz="0.0" iyx="0.0" iyy="1.86719750325683E-06" iyz="-1.21858577871576E-06" izx="0.0" izy="-1.21858577871576E-06" izz="1.21905238907251E-06" />
    </inertial>
  </link>
  <joint name="robotiq_85_left_finger_joint" type="revolute">
    <parent link="robotiq_85_left_knuckle_link" />
    <child link="robotiq_85_left_finger_link" />
    <origin rpy="0 0 0" xyz="-0.00408552455 -0.03148604435 0.0" />
    <axis xyz="0 0 1" />
    <limit lower="0" upper="0" effort="0.1" velocity="0.1" />
  </joint>
  <joint name="robotiq_85_right_finger_joint" type="revolute">
    <parent link="robotiq_85_right_knuckle_link" />
    <child link="robotiq_85_right_finger_link" />
    <origin rpy="0 0 0" xyz="-0.00408552455 -0.03148604435 0.0" />
    <axis xyz="0 0 1" />
    <limit lower="0" upper="0" effort="0.1" velocity="0.1" />
  </joint>
  <link name="robotiq_85_left_finger_link">
    <visual>
      <geometry>
        <mesh filename="assets/robotiq_85_finger_link.stl" />
      </geometry>
    </visual>
    <collision>
      <geometry>
        <mesh filename="assets/robotiq_85_finger_link.stl" />
      </geometry>
    </collision>
    <inertial>
      <mass value="0.027309" />
      <origin xyz="0.0 0.0 0.0" />
      <inertia ixx="0.000003" ixy="-0.000002" ixz="0.000000" iyx="-0.000002" iyy="0.000021" iyz="0.000000" izx="0.000000" izy="0.000000" izz="0.000020" />
    </inertial>
  </link>
  <link name="robotiq_85_right_finger_link">
    <visual>
      <geometry>
        <mesh filename="assets/robotiq_85_finger_link.stl" />
      </geometry>
    </visual>
    <collision>
      <geometry>
        <mesh filename="assets/robotiq_85_finger_link.stl" />
      </geometry>
    </collision>
    <inertial>
      <mass value="0.027309" />
      <origin xyz="0.0 0.0 0.0" />
      <inertia ixx="0.000003" ixy="-0.000002" ixz="0.000000" iyx="-0.000002" iyy="0.000021" iyz="0.000000" izx="0.000000" izy="0.000000" izz="0.000020" />
    </inertial>
  </link>
  <joint name="robotiq_85_left_inner_knuckle_joint" type="continuous">
    <parent link="robotiq_85_base_link" />
    <child link="robotiq_85_left_inner_knuckle_link" />
    <axis xyz="0 0 1" />
    <origin rpy="3.141592653589793 0.0 0.0" xyz="0.06142 0.0127 0" />
    <limit effort="0.1" lower="-3.14" upper="3.14" velocity="100.0" />
    <mimic joint="robotiq_85_left_knuckle_joint" offset="0" />
  </joint>
  <joint name="robotiq_85_right_inner_knuckle_joint" type="continuous">
    <parent link="robotiq_85_base_link" />
    <child link="robotiq_85_right_inner_knuckle_link" />
    <axis xyz="0 0 1" />
    <origin rpy="0 0 0" xyz="0.06142 -0.0127 0" />
    <limit effort="0.1" lower="-3.14" upper="3.14" velocity="100.0" />
    <mimic joint="robotiq_85_left_knuckle_joint" offset="0" />
  </joint>
  <link name="robotiq_85_left_inner_knuckle_link">
    <visual>
      <geometry>
        <mesh filename="assets/robotiq_85_inner_knuckle_link.stl" />
      </geometry>
    </visual>
    <collision>
      <geometry>
        <mesh filename="assets/robotiq_85_inner_knuckle_link.stl" />
      </geometry>
    </collision>
    <inertial>
      <mass value="0.029951" />
      <origin xyz="0.0 0.0 0.0" />
      <inertia ixx="0.000039" ixy="0.000000" ixz="0.000000" iyx="0.000000" iyy="0.000005" iyz="0.000000" izx="0.000000" izy="0.000000" izz="0.000035" />
    </inertial>
  </link>
  <link name="robotiq_85_right_inner_knuckle_link">
    <visual>
      <geometry>
        <mesh filename="assets/robotiq_85_inner_knuckle_link.stl" />
      </geometry>
    </visual>
    <collision>
      <geometry>
        <mesh filename="assets/robotiq_85_inner_knuckle_link.stl" />
      </geometry>
    </collision>
    <inertial>
      <mass value="0.029951" />
      <origin xyz="0.0 0.0 0.0" />
      <inertia ixx="0.000039" ixy="0.000000" ixz="0.000000" iyx="0.000000" iyy="0.000005" iyz="0.000000" izx="0.000000" izy="0.000000" izz="0.000035" />
    </inertial>
  </link>
  <joint name="robotiq_85_left_finger_tip_joint" type="continuous">
    <parent link="robotiq_85_left_inner_knuckle_link" />
    <child link="robotiq_85_left_finger_tip_link" />
    <axis xyz="0 0 1" />
    <origin rpy="0.0 0.0 0.0" xyz="0.04303959807 -0.03759940821 0.0" />
    <limit effort="0.1" lower="-3.14" upper="3.14" velocity="100.0" />
    <mimic joint="robotiq_85_left_knuckle_joint" multiplier="-1" />
  </joint>
  <joint name="robotiq_85_right_finger_tip_joint" type="continuous">
    <parent link="robotiq_85_right_inner_knuckle_link" />
    <child link="robotiq_85_right_finger_tip_link" />
    <axis xyz="0 0 1" />
    <origin rpy="0.0 0.0 0.0" xyz="0.04303959807 -0.03759940821  0.0" />
    <limit effort="0.1" lower="-3.14" upper="3.14" velocity="100.0" />
    <mimic joint="robotiq_85_left_knuckle_joint" multiplier="-1" />
  </joint>
  <link name="robotiq_85_left_finger_tip_link">
    <visual>
      <geometry>
        <mesh filename="assets/robotiq_85_finger_tip_link.stl" />
      </geometry>
    </visual>
    <collision>
      <geometry>
        <mesh filename="assets/robotiq_85_finger_tip_link.stl" />
      </geometry>
    </collision>
    <inertial>
      <mass value="0.019555" />
      <origin xyz="0.0 0.0 0.0" />
      <inertia ixx="0.000002" ixy="0.000000" ixz="0.000000" iyx="0.000000" iyy="0.000005" iyz="0.000000" izx="0.000000" izy="0.000000" izz="0.000006" />
    </inertial>
  </link>
  <link name="robotiq_85_right_finger_tip_link">
    <visual>
      <geometry>
        <mesh filename="assets/robotiq_85_finger_tip_link.stl" />
      </geometry>
    </visual>
    <collision>
      <geometry>
        <mesh filename="assets/robotiq_85_finger_tip_link.stl" />
      </geometry>
    </collision>
    <inertial>
      <mass value="0.019555" />
      <origin xyz="0.0 0.0 0.0" />
      <inertia ixx="0.000002" ixy="0.000000" ixz="0.000000" iyx="0.000000" iyy="0.000005" iyz="0.000000" izx="0.000000" izy="0.000000" izz="0.000006" />
    </inertial>
  </link>
  <!-- Improve grasping physics -->
  <!-- Mimic joints -->
  <!-- Gazebo FT sensor plugin -->
  <!-- Gazebo grasping plugin -->
</robot>